<?xml version="1.0"?>
<robot name="diff_robot">


<material name="black">
    <color rgba="0 0 0 1.0"/>
</material>

<material name="grey">
    <color rgba="0.7 0.7 0.7 1.0"/>
</material>

<material name="green">
    <color rgba="0.0 0.6 0 1.0"/>
</material>

<material name="white">
    <color rgba="1 1 1 1.0"/>
</material>

<link name="base_footprint">
    <inertial>
      <mass value="0.0"/>
      <origin xyz="0 0 0" rpy="0 0 0"/>
      <inertia ixx="0.0" ixy="0.0" ixz="0.0" iyy="0.0" iyz="0.0" izz="0.0"/>
    </inertial>
</link>

<link name="base_link">
    <inertial>
        <origin xyz="0.0 0.0 0.0" rpy="0.0 0.0 0.0"/>
        <mass value="0.1"/>
        <inertia ixx="0.001665" ixy="0.0" ixz="0.0" iyy="0.00441225" iyz="0.0" izz="0.00541625"/>
    </inertial>
    <visual>
        <geometry>  
            <box size="0.7 0.4 0.2"/> 
        </geometry>   
        <origin xyz="0.0 0.0 0.1" rpy="0.0 0.0 0.0"/> 
        <material name="green"/>
    </visual>
</link>

<link name="left_wheel">
    <inertial>
        <origin xyz="0.0 0.0 0.0" rpy="0.0 0.0 0.0"/>
        <mass value="0.3"/>
        <inertia ixx="0.00081252" ixy="0.0" ixz="0.0" iyy="0.00081252" iyz="0.0" izz="0.0015"/>
    </inertial>
    <visual>
        <geometry>
            <cylinder radius="0.1" length="0.05"/>
        </geometry>
        <origin xyz="0.0 0.0 0.0" rpy="1.57 0.0 0.0"/>
        <material name="black"/>     
    </visual>
    <collision>
        <geometry>
            <cylinder radius="0.1" length="0.05"/>
        </geometry>
        <origin xyz="0.0 0.0 0.0" rpy="1.57 0.0 0.0"/>
    </collision>
</link>

<link name="right_wheel">
    <inertial>
        <origin xyz="0.0 0.0 0.0" rpy="0.0 0.0 0.0"/>
        <mass value="0.3"/>
        <inertia ixx="0.00081252" ixy="0.0" ixz="0.0" iyy="0.00081252" iyz="0.0" izz="0.0015"/>
    </inertial>
    <visual>
        <geometry>
            <cylinder radius="0.1" length="0.05"/>
        </geometry>
        <origin xyz="0.0 0.0 0.0" rpy="1.57 0.0 0.0"/>
        <material name="black"/>     
    </visual>
    <collision>
        <geometry>
            <cylinder radius="0.1" length="0.05"/>
        </geometry>
        <origin xyz="0.0 0.0 0.0" rpy="1.57 0.0 0.0"/>
    </collision>
</link>

<link name="caster_wheel">
    <inertial>
        <origin xyz="0.0 0.0 0.0" rpy="0.0 0.0 0.0"/>
        <mass value="0.1"/>
        <inertia ixx="0.00016666" ixy="0.0" ixz="0.0" iyy="0.00016666" iyz="0.0" izz="0.00016666"/>
    </inertial>
    <visual>
        <geometry>
            <sphere radius="0.05"/>
        </geometry>
        <origin xyz="0.0 0.0 0.0" rpy="0.0 0.0 0.0"/>
        <material name="black"/>            
    </visual>
    <collision>
        <geometry>
            <sphere radius="0.05"/>
        </geometry>
        <origin xyz="0.0 0.0 0.0" rpy="0.0 0.0 0.0"/>
    </collision>
</link>




<link name="imu_link">
    <visual>
      <origin rpy="0 0 0" xyz="0 0 0.0"/>
      <geometry>
        <box size="0.01 0.01 0.01"/>
      </geometry>
    </visual>
  </link>

  <link name="lidar_link">
    <visual>
        <geometry>      
            <cylinder radius="0.1" length="0.05"/>
        </geometry>
        <origin xyz="0.0 0.0 0.0" rpy="0.0 0.0 0.0"/>
        <material name="white"/>  
    </visual>
    <collision>
        <geometry>
            <cylinder radius="0.05" length="0.05"/>
        </geometry>
        <origin xyz="0.0 0.0 0.0" rpy="0.0 0.0 0.0"/>
    </collision>
    <inertial>
        <mass value="0.114" />
        <origin xyz="0 0 0" />
        <inertia ixx="0.001" ixy="0.0" ixz="0.0"
                 iyy="0.001" iyz="0.0"
                 izz="0.001" />
      </inertial>
</link>




<joint name="base_footprint_to_base_link" type="fixed">
    <parent link="base_footprint"/>
    <child link="base_link"/>
    <origin xyz="0 0 0.0" rpy="0 0 0"/>
</joint>

<joint name="imu_joint" type="fixed">
    <parent link="base_link"/>
    <child link="imu_link"/>
    <origin xyz="0.1 0.1 0.1" rpy="0.0 0.0 0.0"/>
</joint>

<!-- <joint name="base_joint" type="fixed">
    <parent link="base_link"/>
    <child link="base_footprint"/>
    <origin xyz="0.0 0.0 0.05" rpy="0.0 0.0 0.0"/>
</joint> -->

<joint name="base_lidar_joint" type="fixed">
    <parent link="base_link"/>
    <child link="lidar_link"/>
    <origin xyz="0.0 0.0 0.225" rpy="0.0 0.0 0.0"/>
</joint>

<joint name="left_wheel_joint" type="continuous">
    <parent link="base_link"/>
    <child link="left_wheel"/>
    <origin xyz="-0.175 0.225 0.0" rpy="0 0.0 0.0"/>  
    <axis xyz="0.0 1.0 0.0"/>
    <dynamics damping="0.2" friction="1.0"/>
    <limit effort="100" velocity="1.0"/>
</joint>
<joint name="right_wheel_joint" type="continuous">
    <parent link="base_link"/>
    <child link="right_wheel"/>
    <origin xyz="-0.175 -0.225 0.0" rpy="0 0.0 0.0"/>  
    <axis xyz="0.0 1.0 0.0"/>
    <dynamics damping="0.2" friction="1.0"/>
    <limit effort="100" velocity="1.0"/>
</joint>

<joint name="caster_wheel_joint" type="fixed">
    <parent link="base_link"/>
    <child link="caster_wheel"/>
    <dynamics damping="0.2" friction="0.1"/>
    <origin xyz="0.2 0.0 -0.05" rpy="0.0 0.0 0.0"/>
</joint>



<gazebo>
    <plugin name="diff_drive" filename="libgazebo_ros_diff_drive.so">
        <ros>    <remapping>/tf:=tf</remapping>    </ros>
        <update_rate>100</update_rate>
        <!-- wheel info -->
        <left_joint>left_wheel_joint</left_joint>
        <right_joint>right_wheel_joint</right_joint>
        <wheel_separation>0.38</wheel_separation>
        <wheel_diameter>0.2</wheel_diameter>

        <!-- Limits -->
        <max_wheel_torque>200</max_wheel_torque>
        <max_wheel_acceleration>10.0</max_wheel_acceleration>

        <!-- Output -->
        <odometry_topic>odom</odometry_topic>
        <odometry_frame>odom</odometry_frame>
        <robot_base_frame>base_footprint</robot_base_frame>

        <publish_odom>true</publish_odom>
        <publish_odom_tf>true</publish_odom_tf>
        <publish_wheel_tf>true</publish_wheel_tf>
        <command_topic>cmd_vel</command_topic>
    </plugin>
</gazebo>

<gazebo reference="imu_link">
    <sensor name="imu" type="imu">
        <always_on>true</always_on>
        <update_rate>5</update_rate>
        <plugin name="imu_plugin" filename="libgazebo_ros_imu_sensor.so">
            <ros>
                <remapping>~/out:=imu</remapping>
            </ros>
        </plugin>
    </sensor>
</gazebo>

<gazebo reference="lidar_link">
    <sensor name="laser" type="ray">
        <pose> 0 0 0 0 0 0 </pose>
        <visualize>true</visualize>
        <update_rate>50</update_rate>
        <ray>
            <scan>
                <horizontal>
                    <samples>720</samples>
                    <min_angle>-3.14</min_angle>
                    <max_angle>3.14</max_angle>
                </horizontal>
            </scan>
            <range>
                <min>0.1</min>
                <max>12</max>
            </range>
            <noise>
                <type>gaussian</type>
                <!-- Noise parameters based on published spec for Hokuyo laser
                        achieving "+-30mm" accuracy at range < 10m.  A mean of 0.0m and
                        stddev of 0.01m will put 99.7% of samples within 0.03m of the true
                        reading. -->
                <mean>0.0</mean>
                <stddev>0.01</stddev>
            </noise>
        </ray>
        <plugin name="laser_controller" filename="libgazebo_ros_ray_sensor.so">
            <ros>
                <argument>~/out:=scan</argument>
            </ros>
            <output_type>sensor_msgs/LaserScan</output_type>
            <frame_name>lidar_link</frame_name>
        </plugin>
    </sensor>
</gazebo>


<gazebo>
    <plugin name="diff_robot_joint_state" filename="libgazebo_ros_joint_state_publisher.so">
        <ros>
          <!-- <namespace>/tb3</namespace> -->
          <remapping>~/out:=joint_states</remapping>
        </ros>
        <update_rate>30</update_rate>
        <joint_name>left_wheel_joint</joint_name>
        <joint_name>right_wheel_joint</joint_name>
      </plugin>
</gazebo>

<gazebo reference="base_link">
    <material>Gazebo/Green</material>
</gazebo>
<gazebo reference="right_wheel">
    <material>Gazebo/Black</material>
</gazebo>
<gazebo reference="left_wheel">
    <material>Gazebo/Black</material>
</gazebo>
<gazebo reference="caster_wheel">
    <material>Gazebo/Black</material>
</gazebo>


</robot>